Workbook

Sheet Dane
A1: test_id | B1: dataset_name | C1: classifier_name | D1: reduction_name | E1: training_time | F1: train_set_size | G1: test_set_size | H1: execution_time | I1: correct_predictions | J1: incorrect_predictions | K1: accuracy | L1: precision | M1: recall | N1: f1_score | O1: pixel_normalization_rate | P1: num_segments | Q1: training_set_limit | R1: n_components
A2: 81 | B2: Arabic | C2: K-Nearest Neighbors | D2: Brak redukcji | E2: 0.0433186 | F2: 60000 | G2: 10000 | H2: 21.586998 | I2: 9714 | J2: 286 | K2: 0.9714 | L2: 0.97203331 | M2: 0.9714 | N2: 0.97143593 | O2: 0.5 | P2: 7 | Q2: 99999999 | R2: 784
A3: 97 | B3: Arabic | C3: K-Nearest Neighbors | D3: Flood Fill | E3: 0.0080118 | F3: 60000 | G3: 10000 | H3: 15.981876 | I3: 9610 | J3: 390 | K3: 0.961 | L3: 0.96133952 | M3: 0.961 | N3: 0.96100818 | O3: 0.22858051 | P3: 7 | Q3: 99999999 | R3: 43
A4: 89 | B4: Arabic | C4: K-Nearest Neighbors | D4: LDA | E4: 0.1145143 | F4: 60000 | G4: 10000 | H4: 14.22364 | I4: 9549 | J4: 451 | K4: 0.9549 | L4: 0.95490214 | M4: 0.9549 | N4: 0.95480551 | O4: 0.5 | P4: 7 | Q4: 99999999 | R4: 9
A5: 85 | B5: Arabic | C5: K-Nearest Neighbors | D5: PCA | E5: 0.0077561 | F5: 60000 | G5: 10000 | H5: 11.344126 | I5: 9829 | J5: 171 | K5: 0.9829 | L5: 0.98294719 | M5: 0.9829 | N5: 0.98288708 | O5: 0.5 | P5: 7 | Q5: 99999999 | R5: 43
A6: 93 | B6: Arabic | C6: K-Nearest Neighbors | D6: UMAP | E6: 0.0074387 | F6: 60000 | G6: 10000 | H6: 159.04236 | I6: 9716 | J6: 284 | K6: 0.9716 | L6: 0.97190231 | M6: 0.9716 | N6: 0.97160443 | O6: 0.5 | P6: 7 | Q6: 99999999 | R6: 43
A7: 83 | B7: Arabic | C7: Multi-Layer Perceptron | D7: Brak redukcji | E7: 233.86872 | F7: 60000 | G7: 10000 | H7: 247.0598 | I7: 9810 | J7: 190 | K7: 0.981 | L7: 0.98106903 | M7: 0.981 | N7: 0.98101775 | O7: 0.5 | P7: 7 | Q7: 99999999 | R7: 784
A8: 99 | B8: Arabic | C8: Multi-Layer Perceptron | D8: Flood Fill | E8: 874.67321 | F8: 60000 | G8: 10000 | H8: 890.32681 | I8: 9805 | J8: 195 | K8: 0.9805 | L8: 0.98055894 | M8: 0.9805 | N8: 0.98051084 | O8: 0.22858051 | P8: 7 | Q8: 99999999 | R8: 43
A9: 91 | B9: Arabic | C9: Multi-Layer Perceptron | D9: LDA | E9: 230.04759 | F9: 60000 | G9: 10000 | H9: 243.57354 | I9: 9515 | J9: 485 | K9: 0.9515 | L9: 0.95172257 | M9: 0.9515 | N9: 0.95152706 | O9: 0.5 | P9: 7 | Q9: 99999999 | R9: 9
A10: 87 | B10: Arabic | C10: Multi-Layer Perceptron | D10: PCA | E10: 80.924376 | F10: 60000 | G10: 10000 | H10: 90.42741 | I10: 9838 | J10: 162 | K10: 0.9838 | L10: 0.98386229 | M10: 0.9838 | N10: 0.98380005 | O10: 0.5 | P10: 7 | Q10: 99999999 | R10: 43
A11: 95 | B11: Arabic | C11: Multi-Layer Perceptron | D11: UMAP | E11: 497.86331 | F11: 60000 | G11: 10000 | H11: 652.30315 | I11: 9707 | J11: 293 | K11: 0.9707 | L11: 0.97104663 | M11: 0.9707 | N11: 0.97070636 | O11: 0.5 | P11: 7 | Q11: 99999999 | R11: 43
A12: 84 | B12: Arabic | C12: Support Vector Machine | D12: Brak redukcji | E12: 156.95868 | F12: 60000 | G12: 10000 | H12: 234.45229 | I12: 9813 | J12: 187 | K12: 0.9813 | L12: 0.98134644 | M12: 0.9813 | N12: 0.98131045 | O12: 0.5 | P12: 7 | Q12: 99999999 | R12: 784
A13: 100 | B13: Arabic | C13: Support Vector Machine | D13: Flood Fill | E13: 22.073519 | F13: 60000 | G13: 10000 | H13: 43.234459 | I13: 9702 | J13: 298 | K13: 0.9702 | L13: 0.97036015 | M13: 0.9702 | N13: 0.9702193 | O13: 0.22858051 | P13: 7 | Q13: 99999999 | R13: 43
... A121: 114 | B121: USPS | C121: XGBoost | D121: UMAP | E121: 2.5778076 | F121: 7291 | G121: 2007 | H121: 29.321777 | I121: 1857 | J121: 150 | K121: 0.92526158 | L121: 0.92328982 | M121: 0.91622343 | N121: 0.91911372 | O121: 0.5 | P121: 7 | Q121: 99999999 | R121: 43

Sheet Tabele
A1: Dataset | B1: Classification | C1: Reduction | D1: Accuracy
A2: =Dane!B2 -> Arabic | B2: =Dane!C2 -> K-Nearest Neighbors | C2: =Dane!D2 -> Brak redukcji | D2: =Dane!K2 -> 0.9714 | F2: Maksimum z Accuracy | G2: Etykiety kolumn
A3: =Dane!B3 -> Arabic | B3: =Dane!C3 -> K-Nearest Neighbors | C3: =Dane!D3 -> Flood Fill | D3: =Dane!K3 -> 0.961 | F3: Etykiety wierszy | G3: Brak redukcji | H3: Flood Fill | I3: LDA | J3: PCA | K3: UMAP
A4: =Dane!B4 -> Arabic | B4: =Dane!C4 -> K-Nearest Neighbors | C4: =Dane!D4 -> LDA | D4: =Dane!K4 -> 0.9549 | F4: K-Nearest Neighbors | G4: 0.9714 | H4: 0.961 | I4: 0.9549 | J4: 0.9829 | K4: 0.9716
A5: =Dane!B5 -> Arabic | B5: =Dane!C5 -> K-Nearest Neighbors | C5: =Dane!D5 -> PCA | D5: =Dane!K5 -> 0.9829 | F5: Multi-Layer Perceptron | G5: 0.981 | H5: 0.9805 | I5: 0.9515 | J5: 0.9838 | K5: 0.9707
A6: =Dane!B6 -> Arabic | B6: =Dane!C6 -> K-Nearest Neighbors | C6: =Dane!D6 -> UMAP | D6: =Dane!K6 -> 0.9716 | F6: Support Vector Machine | G6: 0.9813 | H6: 0.9702 | I6: 0.9548 | J6: 0.9839 | K6: 0.9705
A7: =Dane!B7 -> Arabic | B7: =Dane!C7 -> Multi-Layer Perceptron | C7: =Dane!D7 -> Brak redukcji | D7: =Dane!K7 -> 0.981 | F7: XGBoost | G7: 0.9725 | H7: 0.9794 | I7: 0.953 | J7: 0.9749 | K7: 0.9711
A8: =Dane!B8 -> Arabic | B8: =Dane!C8 -> Multi-Layer Perceptron | C8: =Dane!D8 -> Flood Fill | D8: =Dane!K8 -> 0.9805
A9: =Dane!B9 -> Arabic | B9: =Dane!C9 -> Multi-Layer Perceptron | C9: =Dane!D9 -> LDA | D9: =Dane!K9 -> 0.9515
A10: =Dane!B10 -> Arabic | B10: =Dane!C10 -> Multi-Layer Perceptron | C10: =Dane!D10 -> PCA | D10: =Dane!K10 -> 0.9838
A11: =Dane!B11 -> Arabic | B11: =Dane!C11 -> Multi-Layer Perceptron | C11: =Dane!D11 -> UMAP | D11: =Dane!K11 -> 0.9707
A12: =Dane!B12 -> Arabic | B12: =Dane!C12 -> Support Vector Machine | C12: =Dane!D12 -> Brak redukcji | D12: =Dane!K12 -> 0.9813
A13: =Dane!B13 -> Arabic | B13: =Dane!C13 -> Support Vector Machine | C13: =Dane!D13 -> Flood Fill | D13: =Dane!K13 -> 0.9702
A14: =Dane!B14 -> Arabic | B14: =Dane!C14 -> Support Vector Machine | C14: =Dane!D14 -> LDA | D14: =Dane!K14 -> 0.9548
A15: =Dane!B15 -> Arabic | B15: =Dane!C15 -> Support Vector Machine | C15: =Dane!D15 -> PCA | D15: =Dane!K15 -> 0.9839
A16: =Dane!B16 -> Arabic | B16: =Dane!C16 -> Support Vector Machine | C16: =Dane!D16 -> UMAP | D16: =Dane!K16 -> 0.9705
A17: =Dane!B17 -> Arabic | B17: =Dane!C17 -> XGBoost | C17: =Dane!D17 -> Brak redukcji | D17: =Dane!K17 -> 0.9725
A18: =Dane!B18 -> Arabic | B18: =Dane!C18 -> XGBoost | C18: =Dane!D18 -> Flood Fill | D18: =Dane!K18 -> 0.9794
A19: =Dane!B19 -> Arabic | B19: =Dane!C19 -> XGBoost | C19: =Dane!D19 -> LDA | D19: =Dane!K19 -> 0.953
... A21: =Dane!B21 -> Arabic | B21: =Dane!C21 -> XGBoost | C21: =Dane!D21 -> UMAP | D21: =Dane!K21 -> 0.9711
A22: Dataset | B22: Classification | C22: Reduction | D22: Accuracy | F22: Maksimum z Accuracy | G22: Etykiety kolumn
A23: =Dane!B22 -> EMNIST-Balanced | B23: =Dane!C22 -> K-Nearest Neighbors | C23: =Dane!D22 -> Brak redukcji | D23: =Dane!K22 -> 0.74696809 | F23: Etykiety wierszy | G23: Brak redukcji | H23: Flood Fill | I23: LDA | J23: PCA | K23: UMAP
A24: =Dane!B23 -> EMNIST-Balanced | B24: =Dane!C23 -> K-Nearest Neighbors | C24: =Dane!D23 -> Flood Fill | D24: =Dane!K23 -> 0.66239362 | F24: K-Nearest Neighbors | G24: 0.74696809 | H24: 0.66239362 | I24: 0.74457447 | J24: 0.80702128 | K24: 0.71845745
A25: =Dane!B24 -> EMNIST-Balanced | B25: =Dane!C24 -> K-Nearest Neighbors | C25: =Dane!D24 -> LDA | D25: =Dane!K24 -> 0.74457447 | F25: Multi-Layer Perceptron | G25: 0.80053191 | H25: 0.75952128 | I25: 0.76643617 | J25: 0.82356383 | K25: 0.71478723
A26: =Dane!B25 -> EMNIST-Balanced | B26: =Dane!C25 -> K-Nearest Neighbors | C26: =Dane!D25 -> PCA | D26: =Dane!K25 -> 0.80702128 | F26: Support Vector Machine | G26: 0.82723404 | H26: 0.71526596 | I26: 0.81101064 | J26: 0.85079787 | K26: 0.70382979
A27: =Dane!B26 -> EMNIST-Balanced | B27: =Dane!C26 -> K-Nearest Neighbors | C27: =Dane!D26 -> UMAP | D27: =Dane!K26 -> 0.71845745 | F27: XGBoost | G27: 0.77367021 | H27: 0.75042553 | I27: 0.73856383 | J27: 0.76265957 | K27: 0.73941489
A28: =Dane!B27 -> EMNIST-Balanced | B28: =Dane!C27 -> Multi-Layer Perceptron | C28: =Dane!D27 -> Brak redukcji | D28: =Dane!K27 -> 0.80053191
A29: =Dane!B28 -> EMNIST-Balanced | B29: =Dane!C28 -> Multi-Layer Perceptron | C29: =Dane!D28 -> Flood Fill | D29: =Dane!K28 -> 0.75952128
A30: =Dane!B29 -> EMNIST-Balanced | B30: =Dane!C29 -> Multi-Layer Perceptron | C30: =Dane!D29 -> LDA | D30: =Dane!K29 -> 0.76643617
A31: =Dane!B30 -> EMNIST-Balanced | B31: =Dane!C30 -> Multi-Layer Perceptron | C31: =Dane!D30 -> PCA | D31: =Dane!K30 -> 0.82356383
A32: =Dane!B31 -> EMNIST-Balanced | B32: =Dane!C31 -> Multi-Layer Perceptron | C32: =Dane!D31 -> UMAP | D32: =Dane!K31 -> 0.71478723
A33: =Dane!B32 -> EMNIST-Balanced | B33: =Dane!C32 -> Support Vector Machine | C33: =Dane!D32 -> Brak redukcji | D33: =Dane!K32 -> 0.82723404
A34: =Dane!B33 -> EMNIST-Balanced | B34: =Dane!C33 -> Support Vector Machine | C34: =Dane!D33 -> Flood Fill | D34: =Dane!K33 -> 0.71526596
A35: =Dane!B34 -> EMNIST-Balanced | B35: =Dane!C34 -> Support Vector Machine | C35: =Dane!D34 -> LDA | D35: =Dane!K34 -> 0.81101064
A36: =Dane!B35 -> EMNIST-Balanced | B36: =Dane!C35 -> Support Vector Machine | C36: =Dane!D35 -> PCA | D36: =Dane!K35 -> 0.85079787
A37: =Dane!B36 -> EMNIST-Balanced | B37: =Dane!C36 -> Support Vector Machine | C37: =Dane!D36 -> UMAP | D37: =Dane!K36 -> 0.70382979
A38: =Dane!B37 -> EMNIST-Balanced | B38: =Dane!C37 -> XGBoost | C38: =Dane!D37 -> Brak redukcji | D38: =Dane!K37 -> 0.77367021
A39: =Dane!B38 -> EMNIST-Balanced | B39: =Dane!C38 -> XGBoost | C39: =Dane!D38 -> Flood Fill | D39: =Dane!K38 -> 0.75042553
... A41: =Dane!B40 -> EMNIST-Balanced | B41: =Dane!C40 -> XGBoost | C41: =Dane!D40 -> PCA | D41: =Dane!K40 -> 0.76265957
A42: =Dane!B41 -> EMNIST-Balanced | B42: =Dane!C41 -> XGBoost | C42: =Dane!D41 -> UMAP | D42: =Dane!K41 -> 0.73941489 | F42: Maksimum z Accuracy | G42: Etykiety kolumn
...

Sheet Dane corrupted
A1: test_id | B1: dataset_name | C1: classifier_name | D1: reduction_name | E1: training_time | F1: train_set_size | G1: test_set_size | H1: execution_time | I1: correct_predictions | J1: incorrect_predictions | K1: accuracy | L1: precision | M1: recall | N1: f1_score | O1: pixel_normalization_rate | P1: num_segments | Q1: training_set_limit | R1: n_components
A2: 21 | B2: MNIST-C (Brightness) | C2: K-Nearest Neighbors | D2: Brak redukcji | E2: 0.0355744 | F2: 60000 | G2: 10000 | H2: 16.435479 | I2: 9625 | J2: 375 | K2: 0.9625 | L2: 0.96310316 | M2: 0.96194103 | N2: 0.96232152 | O2: 0.5 | P2: 7 | Q2: 99999999 | R2: 784
A3: 37 | B3: MNIST-C (Brightness) | C3: K-Nearest Neighbors | D3: Flood Fill | E3: 0.0034897 | F3: 60000 | G3: 10000 | H3: 7.4888969 | I3: 980 | J3: 9020 | K3: 0.098 | L3: 0.0098 | M3: 0.1 | N3: 0.017850638 | O3: 0.22858051 | P3: 7 | Q3: 99999999 | R3: 43
A4: 29 | B4: MNIST-C (Brightness) | C4: K-Nearest Neighbors | D4: LDA | E4: 0.080101 | F4: 60000 | G4: 10000 | H4: 10.267389 | I4: 9169 | J4: 831 | K4: 0.9169 | L4: 0.91586441 | M4: 0.91567848 | N4: 0.91560182 | O4: 0.5 | P4: 7 | Q4: 99999999 | R4: 9
A5: 25 | B5: MNIST-C (Brightness) | C5: K-Nearest Neighbors | D5: PCA | E5: 0.0037932 | F5: 60000 | G5: 10000 | H5: 9.244563 | I5: 9748 | J5: 252 | K5: 0.9748 | L5: 0.97493286 | M5: 0.97453953 | N5: 0.97469091 | O5: 0.5 | P5: 7 | Q5: 99999999 | R5: 43
A6: 33 | B6: MNIST-C (Brightness) | C6: K-Nearest Neighbors | D6: UMAP | E6: 0.0032555 | F6: 60000 | G6: 10000 | H6: 102.15828 | I6: 9583 | J6: 417 | K6: 0.9583 | L6: 0.95902482 | M6: 0.95781746 | N6: 0.95818245 | O6: 0.5 | P6: 7 | Q6: 99999999 | R6: 43
A7: 23 | B7: MNIST-C (Brightness) | C7: Multi-Layer Perceptron | D7: Brak redukcji | E7: 191.0014 | F7: 60000 | G7: 10000 | H7: 202.34836 | I7: 9767 | J7: 233 | K7: 0.9767 | L7: 0.97652846 | M7: 0.97642085 | N7: 0.97643392 | O7: 0.5 | P7: 7 | Q7: 99999999 | R7: 784
A8: 39 | B8: MNIST-C (Brightness) | C8: Multi-Layer Perceptron | D8: Flood Fill | E8: 10.257892 | F8: 60000 | G8: 10000 | H8: 17.181865 | I8: 1135 | J8: 8865 | K8: 0.1135 | L8: 0.01135 | M8: 0.1 | N8: 0.02038617 | O8: 0.22858051 | P8: 7 | Q8: 99999999 | R8: 43
A9: 31 | B9: MNIST-C (Brightness) | C9: Multi-Layer Perceptron | D9: LDA | E9: 292.81694 | F9: 60000 | G9: 10000 | H9: 303.08455 | I9: 9060 | J9: 940 | K9: 0.906 | L9: 0.90538666 | M9: 0.90504829 | N9: 0.90485661 | O9: 0.5 | P9: 7 | Q9: 99999999 | R9: 9
A10: 27 | B10: MNIST-C (Brightness) | C10: Multi-Layer Perceptron | D10: PCA | E10: 49.962911 | F10: 60000 | G10: 10000 | H10: 57.635941 | I10: 9823 | J10: 177 | K10: 0.9823 | L10: 0.98223704 | M10: 0.98214772 | N10: 0.98218382 | O10: 0.5 | P10: 7 | Q10: 99999999 | R10: 43
A11: 35 | B11: MNIST-C (Brightness) | C11: Multi-Layer Perceptron | D11: UMAP | E11: 85.286964 | F11: 60000 | G11: 10000 | H11: 180.8803 | I11: 9572 | J11: 428 | K11: 0.9572 | L11: 0.95789441 | M11: 0.95676125 | N11: 0.9570874 | O11: 0.5 | P11: 7 | Q11: 99999999 | R11: 43
A12: 24 | B12: MNIST-C (Brightness) | C12: Support Vector Machine | D12: Brak redukcji | E12: 153.4317 | F12: 60000 | G12: 10000 | H12: 230.95839 | I12: 9756 | J12: 244 | K12: 0.9756 | L12: 0.97560904 | M12: 0.97538278 | N12: 0.9754694 | O12: 0.5 | P12: 7 | Q12: 99999999 | R12: 784
A13: 40 | B13: MNIST-C (Brightness) | C13: Support Vector Machine | D13: Flood Fill | E13: 298.3784 | F13: 60000 | G13: 10000 | H13: 347.40346 | I13: 1135 | J13: 8865 | K13: 0.1135 | L13: 0.01135 | M13: 0.1 | N13: 0.02038617 | O13: 0.22858051 | P13: 7 | Q13: 99999999 | R13: 43
... A321: 22 | B321: MNIST-C (Zigzag) | C321: XGBoost | D321: UMAP | E321: 4.721445 | F321: 60000 | G321: 10000 | H321: 111.28574 | I321: 7741 | J321: 2259 | K321: 0.7741 | L321: 0.78285772 | M321: 0.77124515 | N321: 0.77209764 | O321: 0.5 | P321: 7 | Q321: 99999999 | R321: 43

Sheet Tabele Corrupted
A1: Dataset | B1: Classification | C1: Reduction | D1: Accuracy
A2: ='Dane corrupted'!B2 -> MNIST-C (Brightness) | B2: ='Dane corrupted'!C2 -> K-Nearest Neighbors | C2: ='Dane corrupted'!D2 -> Brak redukcji | D2: ='Dane corrupted'!K2 -> 0.9625 | F2: Maksimum z Accuracy | G2: Etykiety kolumn
A3: ='Dane corrupted'!B3 -> MNIST-C (Brightness) | B3: ='Dane corrupted'!C3 -> K-Nearest Neighbors | C3: ='Dane corrupted'!D3 -> Flood Fill | D3: ='Dane corrupted'!K3 -> 0.098 | F3: Etykiety wierszy | G3: Brak redukcji | H3: Flood Fill | I3: LDA | J3: PCA | K3: UMAP
A4: ='Dane corrupted'!B4 -> MNIST-C (Brightness) | B4: ='Dane corrupted'!C4 -> K-Nearest Neighbors | C4: ='Dane corrupted'!D4 -> LDA | D4: ='Dane corrupted'!K4 -> 0.9169 | F4: K-Nearest Neighbors | G4: 0.9714 | H4: 0.961 | I4: 0.9549 | J4: 0.9829 | K4: 0.9716
A5: ='Dane corrupted'!B5 -> MNIST-C (Brightness) | B5: ='Dane corrupted'!C5 -> K-Nearest Neighbors | C5: ='Dane corrupted'!D5 -> PCA | D5: ='Dane corrupted'!K5 -> 0.9748 | F5: Multi-Layer Perceptron | G5: 0.981 | H5: 0.9805 | I5: 0.9515 | J5: 0.9838 | K5: 0.9707
A6: ='Dane corrupted'!B6 -> MNIST-C (Brightness) | B6: ='Dane corrupted'!C6 -> K-Nearest Neighbors | C6: ='Dane corrupted'!D6 -> UMAP | D6: ='Dane corrupted'!K6 -> 0.9583 | F6: Support Vector Machine | G6: 0.9813 | H6: 0.9702 | I6: 0.9548 | J6: 0.9839 | K6: 0.9705
A7: ='Dane corrupted'!B7 -> MNIST-C (Brightness) | B7: ='Dane corrupted'!C7 -> Multi-Layer Perceptron | C7: ='Dane corrupted'!D7 -> Brak redukcji | D7: ='Dane corrupted'!K7 -> 0.9767 | F7: XGBoost | G7: 0.9725 | H7: 0.9794 | I7: 0.953 | J7: 0.9749 | K7: 0.9711
A8: ='Dane corrupted'!B8 -> MNIST-C (Brightness) | B8: ='Dane corrupted'!C8 -> Multi-Layer Perceptron | C8: ='Dane corrupted'!D8 -> Flood Fill | D8: ='Dane corrupted'!K8 -> 0.1135
A9: ='Dane corrupted'!B9 -> MNIST-C (Brightness) | B9: ='Dane corrupted'!C9 -> Multi-Layer Perceptron | C9: ='Dane corrupted'!D9 -> LDA | D9: ='Dane corrupted'!K9 -> 0.906
A10: ='Dane corrupted'!B10 -> MNIST-C (Brightness) | B10: ='Dane corrupted'!C10 -> Multi-Layer Perceptron | C10: ='Dane corrupted'!D10 -> PCA | D10: ='Dane corrupted'!K10 -> 0.9823
A11: ='Dane corrupted'!B11 -> MNIST-C (Brightness) | B11: ='Dane corrupted'!C11 -> Multi-Layer Perceptron | C11: ='Dane corrupted'!D11 -> UMAP | D11: ='Dane corrupted'!K11 -> 0.9572
A12: ='Dane corrupted'!B12 -> MNIST-C (Brightness) | B12: ='Dane corrupted'!C12 -> Support Vector Machine | C12: ='Dane corrupted'!D12 -> Brak redukcji | D12: ='Dane corrupted'!K12 -> 0.9756
A13: ='Dane corrupted'!B13 -> MNIST-C (Brightness) | B13: ='Dane corrupted'!C13 -> Support Vector Machine | C13: ='Dane corrupted'!D13 -> Flood Fill | D13: ='Dane corrupted'!K13 -> 0.1135
A14: ='Dane corrupted'!B14 -> MNIST-C (Brightness) | B14: ='Dane corrupted'!C14 -> Support Vector Machine | C14: ='Dane corrupted'!D14 -> LDA | D14: ='Dane corrupted'!K14 -> 0.9205
A15: ='Dane corrupted'!B15 -> MNIST-C (Brightness) | B15: ='Dane corrupted'!C15 -> Support Vector Machine | C15: ='Dane corrupted'!D15 -> PCA | D15: ='Dane corrupted'!K15 -> 0.9837
A16: ='Dane corrupted'!B16 -> MNIST-C (Brightness) | B16: ='Dane corrupted'!C16 -> Support Vector Machine | C16: ='Dane corrupted'!D16 -> UMAP | D16: ='Dane corrupted'!K16 -> 0.9567
A17: ='Dane corrupted'!B17 -> MNIST-C (Brightness) | B17: ='Dane corrupted'!C17 -> XGBoost | C17: ='Dane corrupted'!D17 -> Brak redukcji | D17: ='Dane corrupted'!K17 -> 0.9696
A18: ='Dane corrupted'!B18 -> MNIST-C (Brightness) | B18: ='Dane corrupted'!C18 -> XGBoost | C18: ='Dane corrupted'!D18 -> Flood Fill | D18: ='Dane corrupted'!K18 -> 0.1135
A19: ='Dane corrupted'!B19 -> MNIST-C (Brightness) | B19: ='Dane corrupted'!C19 -> XGBoost | C19: ='Dane corrupted'!D19 -> LDA | D19: ='Dane corrupted'!K19 -> 0.9154
... A21: ='Dane corrupted'!B21 -> MNIST-C (Brightness) | B21: ='Dane corrupted'!C21 -> XGBoost | C21: ='Dane corrupted'!D21 -> UMAP | D21: ='Dane corrupted'!K21 -> 0.9586
A22: Dataset | B22: Classification | C22: Reduction | D22: Accuracy | F22: Maksimum z Accuracy | G22: Etykiety kolumn
A23: ='Dane corrupted'!B22 -> MNIST-C (Canny Edges) | B23: ='Dane corrupted'!C22 -> K-Nearest Neighbors | C23: ='Dane corrupted'!D22 -> Brak redukcji | D23: ='Dane corrupted'!K22 -> 0.9084 | F23: Etykiety wierszy | G23: Brak redukcji | H23: Flood Fill | I23: LDA | J23: PCA | K23: UMAP
A24: ='Dane corrupted'!B23 -> MNIST-C (Canny Edges) | B24: ='Dane corrupted'!C23 -> K-Nearest Neighbors | C24: ='Dane corrupted'!D23 -> Flood Fill | D24: ='Dane corrupted'!K23 -> 0.9457 | F24: K-Nearest Neighbors | G24: 0.74696809 | H24: 0.66239362 | I24: 0.74457447 | J24: 0.80702128 | K24: 0.71845745
A25: ='Dane corrupted'!B24 -> MNIST-C (Canny Edges) | B25: ='Dane corrupted'!C24 -> K-Nearest Neighbors | C25: ='Dane corrupted'!D24 -> LDA | D25: ='Dane corrupted'!K24 -> 0.8791 | F25: Multi-Layer Perceptron | G25: 0.80053191 | H25: 0.75952128 | I25: 0.76643617 | J25: 0.82356383 | K25: 0.71478723
A26: ='Dane corrupted'!B25 -> MNIST-C (Canny Edges) | B26: ='Dane corrupted'!C25 -> K-Nearest Neighbors | C26: ='Dane corrupted'!D25 -> PCA | D26: ='Dane corrupted'!K25 -> 0.9006 | F26: Support Vector Machine | G26: 0.82723404 | H26: 0.71526596 | I26: 0.81101064 | J26: 0.85079787 | K26: 0.70382979
A27: ='Dane corrupted'!B26 -> MNIST-C (Canny Edges) | B27: ='Dane corrupted'!C26 -> K-Nearest Neighbors | C27: ='Dane corrupted'!D26 -> UMAP | D27: ='Dane corrupted'!K26 -> 0.8717 | F27: XGBoost | G27: 0.77367021 | H27: 0.75042553 | I27: 0.73856383 | J27: 0.76265957 | K27: 0.73941489
A28: ='Dane corrupted'!B27 -> MNIST-C (Canny Edges) | B28: ='Dane corrupted'!C27 -> Multi-Layer Perceptron | C28: ='Dane corrupted'!D27 -> Brak redukcji | D28: ='Dane corrupted'!K27 -> 0.9575
A29: ='Dane corrupted'!B28 -> MNIST-C (Canny Edges) | B29: ='Dane corrupted'!C28 -> Multi-Layer Perceptron | C29: ='Dane corrupted'!D28 -> Flood Fill | D29: ='Dane corrupted'!K28 -> 0.9677
A30: ='Dane corrupted'!B29 -> MNIST-C (Canny Edges) | B30: ='Dane corrupted'!C29 -> Multi-Layer Perceptron | C30: ='Dane corrupted'!D29 -> LDA | D30: ='Dane corrupted'!K29 -> 0.857
A31: ='Dane corrupted'!B30 -> MNIST-C (Canny Edges) | B31: ='Dane corrupted'!C30 -> Multi-Layer Perceptron | C31: ='Dane corrupted'!D30 -> PCA | D31: ='Dane corrupted'!K30 -> 0.9413
A32: ='Dane corrupted'!B31 -> MNIST-C (Canny Edges) | B32: ='Dane corrupted'!C31 -> Multi-Layer Perceptron | C32: ='Dane corrupted'!D31 -> UMAP | D32: ='Dane corrupted'!K31 -> 0.8514
A33: ='Dane corrupted'!B32 -> MNIST-C (Canny Edges) | B33: ='Dane corrupted'!C32 -> Support Vector Machine | C33: ='Dane corrupted'!D32 -> Brak redukcji | D33: ='Dane corrupted'!K32 -> 0.9551
A34: ='Dane corrupted'!B33 -> MNIST-C (Canny Edges) | B34: ='Dane corrupted'!C33 -> Support Vector Machine | C34: ='Dane corrupted'!D33 -> Flood Fill | D34: ='Dane corrupted'!K33 -> 0.9559
A35: ='Dane corrupted'!B34 -> MNIST-C (Canny Edges) | B35: ='Dane corrupted'!C34 -> Support Vector Machine | C35: ='Dane corrupted'!D34 -> LDA | D35: ='Dane corrupted'!K34 -> 0.8861
A36: ='Dane corrupted'!B35 -> MNIST-C (Canny Edges) | B36: ='Dane corrupted'!C35 -> Support Vector Machine | C36: ='Dane corrupted'!D35 -> PCA | D36: ='Dane corrupted'!K35 -> 0.9376
A37: ='Dane corrupted'!B36 -> MNIST-C (Canny Edges) | B37: ='Dane corrupted'!C36 -> Support Vector Machine | C37: ='Dane corrupted'!D36 -> UMAP | D37: ='Dane corrupted'!K36 -> 0.8651
A38: ='Dane corrupted'!B37 -> MNIST-C (Canny Edges) | B38: ='Dane corrupted'!C37 -> XGBoost | C38: ='Dane corrupted'!D37 -> Brak redukcji | D38: ='Dane corrupted'!K37 -> 0.9442
A39: ='Dane corrupted'!B38 -> MNIST-C (Canny Edges) | B39: ='Dane corrupted'!C38 -> XGBoost | C39: ='Dane corrupted'!D38 -> Flood Fill | D39: ='Dane corrupted'!K38 -> 0.9628
... A41: ='Dane corrupted'!B40 -> MNIST-C (Canny Edges) | B41: ='Dane corrupted'!C40 -> XGBoost | C41: ='Dane corrupted'!D40 -> PCA | D41: ='Dane corrupted'!K40 -> 0.8628
A42: ='Dane corrupted'!B41 -> MNIST-C (Canny Edges) | B42: ='Dane corrupted'!C41 -> XGBoost | C42: ='Dane corrupted'!D41 -> UMAP | D42: ='Dane corrupted'!K41 -> 0.8774 | F42: Maksimum z Accuracy | G42: Etykiety kolumn
...
